Workbook

Sheet CAPEX
B2: CAPEX
B5: Totales | C5: =+SUM(C7:C138) | F5: =+SUM(F7:F138)
B6: Conceptos | C6: Valor de adquisición (Sin IVA) | D6: Vida útil (años) | E6: Vida útil (meses) | F6: Amortización o depreciación ($) | H6: Parámetros de vida útil — México (tasa máx. ISR art. 33-34)
B7: [Vehículos] Camioneta/van de instalación (seminueva) | C7: 420000 | D7: 4 | E7: =+D7*12 | F7: =+IF(E7>0,C7/E7,0) | H7: Construcciones / adecuaciones | I7: 5% · 20 años
B8: [Vehículos] Remolque para transporte de paneles | C8: 60000 | D8: 5 | E8: =+D8*12 | F8: =+IF(E8>0,C8/E8,0) | H8: Mobiliario y equipo de oficina | I8: 10% · 10 años
B9: [Herramienta] Kit de herramienta eléctrica (taladros, rotomartillo) | C9: 45000 | D9: 4 | E9: =+D9*12 | F9: =+IF(E9>0,C9/E9,0) | H9: Equipo de cómputo | I9: 30% · 3.3 años
B10: [Herramienta] Herramienta manual e instrumentos de medición eléctrica | C10: 38000 | D10: 4 | E10: =+D10*12 | F10: =+IF(E10>0,C10/E10,0) | H10: Automóviles y vehículos | I10: 25% · 4 años
B11: [Herramienta] Equipo de seguridad en altura (arneses, líneas de vida) | C11: 35000 | D11: 3 | E11: =+D11*12 | F11: =+IF(E11>0,C11/E11,0) | H11: Maquinaria y equipo (general) | I11: 10% · 10 años
B12: [Herramienta] Andamios y escaleras | C12: 28000 | D12: 5 | E12: =+D12*12 | F12: =+IF(E12>0,C12/E12,0) | H12: Herramienta, dados y troqueles | I12: 35% · ≈3 años
B13: [Herramienta] Estación de crimpado y conectorización solar (MC4) | C13: 18000 | D13: 5 | E13: =+D13*12 | F13: =+IF(E13>0,C13/E13,0) | H13: Equipo de comunicación telefónica | I13: 25% · 4 años
B14: [Cómputo] Laptops y equipo de diseño (4) | C14: 80000 | D14: 3 | E14: =+D14*12 | F14: =+IF(E14>0,C14/E14,0) | H14: Gastos diferidos / intangibles | I14: 15% · ≈6.7 años
B15: [Cómputo] Servidor/NAS y sistema de respaldo | C15: 30000 | D15: 4 | E15: =+D15*12 | F15: =+IF(E15>0,C15/E15,0) | H15: Gastos preoperativos | I15: 10% · 10 años
B16: [Cómputo] Smartphones y tablets de campo (3) | C16: 24000 | D16: 2 | E16: =+D16*12 | F16: =+IF(E16>0,C16/E16,0)
B17: [Cómputo] Impresora/multifuncional | C17: 8000 | D17: 4 | E17: =+D17*12 | F17: =+IF(E17>0,C17/E17,0)
B18: [Mobiliario] Mobiliario de oficina (escritorios, sillas, salas) | C18: 55000 | D18: 10 | E18: =+D18*12 | F18: =+IF(E18>0,C18/E18,0)
B19: [Mobiliario] Anaqueles y racks de bodega | C19: 40000 | D19: 10 | E19: =+D19*12 | F19: =+IF(E19>0,C19/E19,0)
B20: [Mobiliario] Adecuación de bodega y oficina (obra menor) | C20: 70000 | D20: 5 | E20: =+D20*12 | F20: =+IF(E20>0,C20/E20,0)
B21: [Mobiliario] Clima / aire acondicionado | C21: 22000 | D21: 10 | E21: =+D21*12 | F21: =+IF(E21>0,C21/E21,0)
B22: [Demostración] Sistema demostrativo showroom (panel+inversor+batería) | C22: 50000 | D22: 5 | E22: =+D22*12 | F22: =+IF(E22>0,C22/E22,0)
B23: [Intangibles SW] Desarrollo App móvil iOS/Android (MVP) | C23: 360000 | D23: 3 | E23: =+D23*12 | F23: =+IF(E23>0,C23/E23,0)
B24: [Intangibles SW] Plataforma de monitoreo + módulo IA (backend) | C24: 260000 | D24: 3 | E24: =+D24*12 | F24: =+IF(E24>0,C24/E24,0)
B25: [Intangibles SW] Implementación CRM/ERP (setup e integración) | C25: 55000 | D25: 3 | E25: =+D25*12 | F25: =+IF(E25>0,C25/E25,0)
B26: [Intangibles SW] Sitio web y e-commerce | C26: 35000 | D26: 3 | E26: =+D26*12 | F26: =+IF(E26>0,C26/E26,0)
B27: [Preoperativos] Registro de marca e identidad visual | C27: 40000 | D27: 5 | E27: =+D27*12 | F27: =+IF(E27>0,C27/E27,0)
... B29: [Preoperativos] Certificaciones (NOM/UL, capacitación CONUEE/CRE) | C29: 32000 | D29: 3 | E29: =+D29*12 | F29: =+IF(E29>0,C29/E29,0)

Sheet OPEX
B2: Porcentaje de prestaciones de ley: | D2: 0.35
B3: Todas las cifras en pesos mexicanos (MXN)
B4: Sueldos (mensual) | D4: Costo Indirecto de Fábrica (mensual) | F4: Productos/Servicios
F5: Sistema Fotovoltaico 4 kWp | H5: Calentador Solar 200 L | J5: Prod/Servicio 3 | L5: Prod/Servicio 4 | N5: Prod/Servicio 5
B6: Concepto | C6: Monto | D6: Concepto | E6: Monto | F6: Concepto | G6: Monto | H6: Concepto | I6: Monto | J6: Concepto | K6: Monto | L6: Concepto | M6: Monto | N6: Concepto | O6: Monto
B7: Total | C7: =+SUM(C9:C52)+C8 | D7: Total | E7: =+SUM(E9:E52)+E8 | F7: Total | G7: =+SUM(G8:G52) | H7: Total | I7: =+SUM(I8:I52) | J7: Total | K7: =+SUM(K8:K52) | L7: Total | M7: =+SUM(M8:M52) | N7: Total | O7: =+SUM(O8:O52)
B8: Prestaciones de ley | C8: =+SUM(C9:C52)*$D$2 | D8: Depreciación/amortización | E8: =+CAPEX!F5 | F8: Paneles solares 8×550 W bifaciales | G8: 28000 | H8: Termotanque tubos al vacío 200 L | I8: 5200
B9: Director General (CEO) | C9: 35000 | D9: Renta de oficina | E9: 12000 | F9: Inversor string 5 kW | G9: 16000 | H9: Estructura y soportería | I9: 900
B10: Líder Comercial / Ventas | C10: 22000 | D10: Renta de bodega/almacén | E10: 8000 | F10: Estructura de montaje y rieles | G10: 8500 | H10: Tubería, conexiones y aislante térmico | I10: 1100
B11: Ingeniero Solar / Diseño y Operaciones | C11: 25000 | D11: Energía eléctrica | E11: 2500 | F11: Cableado, protecciones y tablero | G11: 6500 | H11: Mano de obra de instalación | I11: 600
B12: Instalador líder (cuadrilla) | C12: 14000 | D12: Agua | E12: 600 | F12: Medidor bidireccional e interconexión | G12: 3500
B13: Ayudante de instalación | C13: 9000 | D13: Internet y telefonía | E13: 2500 | F13: Mano de obra de instalación | G13: 7000
B14: Analista Financiero / Administración | C14: 16000 | D14: Software CRM (HubSpot/Pipedrive) | E14: 2800 | F14: Trámites CFE / gestoría | G14: 2500
B15: Growth / Marketing | C15: 18000 | D15: Software ERP/contabilidad (CONTPAQi) | E15: 1800 | F15: Flete y maniobras | G15: 2000
B16: Servicio al cliente / Postventa (medio tiempo) | C16: 8000 | D16: Software monitoreo/IA (cloud + APIs) | E16: 4500
D17: Combustible (van) | E17: 6000
D18: Mantenimiento vehicular | E18: 2000
D19: Casetas y peajes | E19: 1500
D20: Herramienta menor y consumibles (silicón, tornillería) | E20: 3000
D21: EPP y uniformes | E21: 1200
D22: Seguro de responsabilidad civil + equipo | E22: 3500
D23: Seguro de vehículo | E23: 1800
D24: Honorarios contables | E24: 4500
D25: Honorarios legales | E25: 2500
D26: Papelería y artículos de oficina | E26: 800
D27: Servicio de limpieza | E27: 1500
D28: Comisiones bancarias / TPV | E28: 2000
D29: Capacitación y certificación continua | E29: 2000

Sheet Costeo y análisis de rent.
B2: Costeo basado en actividades | C2: Costeo basado en actividades (ABC) — cifras en MXN | D2: =+OPEX!F5 | E2: =+OPEX!H5 | F2: =+OPEX!J5 | G2: =+OPEX!L5 | H2: =+OPEX!N5 | I2: Costo de actividad
C3: % de asignación | D3: 0.75 | E3: 0.25 | I3: =+SUM(D3:H3)
C4: Sueldos | D4: =+$I$4*D3 | E4: =+$I$4*E3 | F4: =+$I$4*F3 | G4: =+$I$4*G3 | H4: =+$I$4*H3 | I4: =+OPEX!C7
C5: % de asignación CIF | D5: 0.7 | E5: 0.3 | I5: =+SUM(D5:H5)
C6: Costos indirectos de fábrica | D6: =+$I$6*D5 | E6: =+$I$6*E5 | F6: =+$I$6*F5 | G6: =+$I$6*G5 | H6: =+$I$6*H5 | I6: =+OPEX!E7
C7: Total | D7: =+D6+D4 | E7: =+E6+E4 | F7: =+F6+F4 | G7: =+G6+G4 | H7: =+H6+H4 | I7: =+I6+I4
C8: Material directo | D8: =+OPEX!G7 | E8: =+OPEX!I7 | F8: =+OPEX!K7 | G8: =+OPEX!M7 | H8: =+OPEX!O7
C9: Unidades producidas mensualmente | D9: 17 | E9: 13
C10: Costo unitario | D10: =+D8+IF(D9>0,D7/D9,0) | E10: =+E8+IF(E9>0,E7/E9,0)
C11: Precio | D11: 112000 | E11: 13500
C12: Margen | D12: =+D11-D10 | E12: =+E11-E10
C13: Punto de equilibrio | D13: =+IF((D11-D8)>0,D7/(D11-D8),0) | E13: =+IF((E11-E8)>0,E7/(E11-E8),0)
B15: Driver de asignación SUELDOS: horas-esfuerzo (FV: diseño+permisos CFE+instalación mayor)
B16: Driver de asignación CIF: uso de bodega, transporte y vehículo (FV ocupa más)
B17: Margen por ABSORCIÓN (incluye overhead). El margen de CONTRIBUCIÓN unitario es: FV 38,000 · Calentador 5,700
B18: Nota: a volumen mes 24 (FV 35u, Cal 25u) el costo unitario baja a 80,435 / 11,094 y ambos quedan positivos.

Sheet Unidades Económicas
B5: Costo de adquisición de consumidores (CAC) — cifras en MXN | I5: LifeTime Value (sobre 2 años) — cifras en MXN
B7: Concepto | C7: Sistema FV Microcrédito | D7: Sistema FV Contado | E7: Calentador Solar | J7: =+'Costeo y análisis de rent.'!D2 | K7: =+'Costeo y análisis de rent.'!E2 | L7: =+'Costeo y análisis de rent.'!F2 | M7: =+'Costeo y análisis de rent.'!G2 | N7: =+'Costeo y análisis de rent.'!H2
B8: Creación de marca | C8: 6000 | D8: 2500 | E8: 1500 | I8: Precio | J8: 112000 | K8: 99000 | L8: 13500
B9: Sitio web (creación y mantenimiento) | C9: 2000 | I9: Costo de material directo | J9: 74000 | K9: 74000 | L9: 7800
B10: Campañas promocionales | C10: 8000 | D10: 4000 | E10: 3000 | I10: Margen Bruto | J10: =+J8-J9 | K10: =+K8-K9 | L10: =+L8-L9
B11: Herramientas de automatización | C11: 3000 | I11: Numero de ventas por cliente sobre 2 años | J11: 1 | K11: 1 | L11: 1.2
B12: Viáticos | I12: LTV | J12: =+J10*J11 | K12: =+K10*K11 | L12: =+L10*L11
B13: Conferencias /Webinars
B14: Publicidad digital | C14: 28000 | D14: 14000 | E14: 8000
B15: Producción de videos | C15: 3000
B16: Regalos y muestras | E16: 1000
B17: Comisiones | C17: 18000 | D17: 9000 | E17: 4000 | I17: Razón de unidades económicas
B18: Agencias
B19: Participación en eventos / ferias | C19: 4000 | I19: Razón unitaria (LTV/CAC): | J19: =+IF(C26>0,J12/C26,0) | K19: =+IF(D26>0,K12/D26,0) | L19: =+IF(E26>0,L12/E26,0)
B20: Realización de eventos | I20: LTV/CAC por producto:
B21: Optimización de motor de busqueda | C21: 2600 | D21: 1500 | E21: 1000
B22: Influencers | C22: 4000 | I22: Resultado | J22: Interpretación
B23: Otros | C23: 3000 | D23: 3000 | E23: 1000 | I23: Si Razón unitaria < 1 | J23: El producto no es rentable
B24: Total | C24: =SUM(C8:C23) | D24: =SUM(D8:D23) | E24: =SUM(E8:E23) | F24: =SUM(F8:F23) | G24: =SUM(G8:G23) | I24: 1 < Razón Unitaria < 2 | J24: Rentable pero problemas de liquidez
B25: Clientes adquiridos | C25: 12 | D25: 5 | E25: 13 | I25: 2 < Razón Unitaria < 3 | J25: Rentable y liquido pero no escalable
B26: CAC | C26: =+IF(C25>0,C24/C25,0) | D26: =+IF(D25>0,D24/D25,0) | E26: =+IF(E25>0,E24/E25,0) | I26: Si Razón unitaria > 3 | J26: Rentable, liquido y escalable

Sheet Resumen operativo
B2: Cifras en pesos mexicanos (MXN)
B3: # | C3: Productos | D3: Precio | E3: C/u directo | F3: CAC
B4: 1 | C4: Sistema FV Microcrédito | D4: 112000 | E4: 74000 | F4: 6800
B5: 2 | C5: Sistema FV Contado | D5: 99000 | E5: 74000 | F5: 6800
B6: 3 | C6: Calentador Solar | D6: 13500 | E6: 7800 | F6: 1500
B7: 4
B8: 5
B9: 6
B10: 7
B11: 8
B12: 9
B13: 10

Sheet Proyección financiera Insumos
B2: # | C2: Ventas en Unidades | D2: Mes 1 | E2: Mes 2 | F2: Mes 3 | G2: Mes 4 | H2: Mes 5 | I2: Mes 6 | J2: Mes 7 | K2: Mes 8 | L2: Mes 9 | M2: Mes 10 | N2: Mes 11 | O2: Mes 12 | P2: Total | Q2: Mes 1 | R2: Mes 2 | S2: Mes 3 | T2: Mes 4 | U2: Mes 5 | V2: Mes 6 | W2: Mes 7 | X2: Mes 8 | Y2: Mes 9 | Z2: Mes 10 | AA2: Mes 11 | AB2: Mes 12 | AC2: Total
B3: =+'Resumen operativo'!B4 | C3: =+IF('Resumen operativo'!C4<>"",'Resumen operativo'!C4,"") | D3: 1 | E3: 2 | F3: 3 | G3: 4 | H3: 5 | I3: 6 | J3: 7 | K3: 8 | L3: 9 | M3: 10 | N3: 11 | O3: 12 | P3: =SUM(D3:O3) | Q3: 13 | R3: 14 | S3: 15 | T3: 16 | U3: 17 | V3: 18 | W3: 19 | X3: 20 | Y3: 21 | Z3: 22 | AA3: 23 | AB3: 24 | AC3: =SUM(Q3:AB3)
B4: =+'Resumen operativo'!B5 | C4: =+IF('Resumen operativo'!C5<>"",'Resumen operativo'!C5,"") | D4: 0 | E4: 1 | F4: 1 | G4: 2 | H4: 2 | I4: 2 | J4: 3 | K4: 3 | L4: 3 | M4: 4 | N4: 4 | O4: 5 | P4: =SUM(D4:O4) | Q4: 5 | R4: 6 | S4: 6 | T4: 7 | U4: 7 | V4: 8 | W4: 8 | X4: 9 | Y4: 9 | Z4: 10 | AA4: 10 | AB4: 11 | AC4: =SUM(Q4:AB4)
B5: =+'Resumen operativo'!B6 | C5: =+IF('Resumen operativo'!C6<>"",'Resumen operativo'!C6,"") | D5: 2 | E5: 3 | F5: 4 | G5: 5 | H5: 6 | I5: 7 | J5: 8 | K5: 9 | L5: 10 | M5: 11 | N5: 12 | O5: 13 | P5: =SUM(D5:O5) | Q5: 14 | R5: 15 | S5: 16 | T5: 17 | U5: 18 | V5: 19 | W5: 20 | X5: 21 | Y5: 22 | Z5: 23 | AA5: 24 | AB5: 25 | AC5: =SUM(Q5:AB5)
B6: =+'Resumen operativo'!B7 | C6: =+IF('Resumen operativo'!C7<>"",'Resumen operativo'!C7,"") | P6: =SUM(D6:O6) | AC6: =SUM(Q6:AB6)
B7: =+'Resumen operativo'!B8 | C7: =+IF('Resumen operativo'!C8<>"",'Resumen operativo'!C8,"") | P7: =SUM(D7:O7) | AC7: =SUM(Q7:AB7)
B8: =+'Resumen operativo'!B9 | C8: =+IF('Resumen operativo'!C9<>"",'Resumen operativo'!C9,"") | P8: =SUM(D8:O8) | AC8: =SUM(Q8:AB8)
B9: =+'Resumen operativo'!B10 | C9: =+IF('Resumen operativo'!C10<>"",'Resumen operativo'!C10,"") | P9: =SUM(D9:O9) | AC9: =SUM(Q9:AB9)
B10: =+'Resumen operativo'!B11 | C10: =+IF('Resumen operativo'!C11<>"",'Resumen operativo'!C11,"") | P10: =SUM(D10:O10) | AC10: =SUM(Q10:AB10)
B11: =+'Resumen operativo'!B12 | C11: =+IF('Resumen operativo'!C12<>"",'Resumen operativo'!C12,"") | P11: =SUM(D11:O11) | AC11: =SUM(Q11:AB11)
B12: =+'Resumen operativo'!B13 | C12: =+IF('Resumen operativo'!C13<>"",'Resumen operativo'!C13,"") | P12: =SUM(D12:O12) | AC12: =SUM(Q12:AB12)
C13: Total | D13: =SUM(D3:D12) | E13: =SUM(E3:E12) | F13: =SUM(F3:F12) | G13: =SUM(G3:G12) | H13: =SUM(H3:H12) | I13: =SUM(I3:I12) | J13: =SUM(J3:J12) | K13: =SUM(K3:K12) | ... AC13: =SUM(AC3:AC12)
B15: # | C15: Ventas en $ | D15: 1 | E15: 2 | F15: 3 | G15: 4 | H15: 5 | I15: 6 | J15: 7 | K15: 8 | L15: 9 | M15: 10 | N15: 11 | O15: 12 | P15: Total | Q15: 1 | R15: 2 | S15: 3 | T15: 4 | U15: 5 | V15: 6 | W15: 7 | X15: 8 | Y15: 9 | Z15: 10 | AA15: 11 | AB15: 12 | AC15: Total
B16: 1 | C16: =+IF(C3<>"",C3,"") | D16: =+D3*'Resumen operativo'!$D4 | E16: =+E3*'Resumen operativo'!$D4 | F16: =+F3*'Resumen operativo'!$D4 | G16: =+G3*'Resumen operativo'!$D4 | H16: =+H3*'Resumen operativo'!$D4 | I16: =+I3*'Resumen operativo'!$D4 | J16: =+J3*'Resumen operativo'!$D4 | K16: =+K3*'Resumen operativo'!$D4 | ... O16: =+O3*'Resumen operativo'!$D4 | P16: =SUM(D16:O16) | Q16: =+Q3*'Resumen operativo'!$D4 | R16: =+R3*'Resumen operativo'!$D4 | S16: =+S3*'Resumen operativo'!$D4 | T16: =+T3*'Resumen operativo'!$D4 | U16: =+U3*'Resumen operativo'!$D4 | V16: =+V3*'Resumen operativo'!$D4 | W16: =+W3*'Resumen operativo'!$D4 | X16: =+X3*'Resumen operativo'!$D4 | ... AB16: =+AB3*'Resumen operativo'!$D4 | AC16: =SUM(Q16:AB16)
B17: 2 | C17: =+IF(C4<>"",C4,"") | D17: =+D4*'Resumen operativo'!$D5 | E17: =+E4*'Resumen operativo'!$D5 | F17: =+F4*'Resumen operativo'!$D5 | G17: =+G4*'Resumen operativo'!$D5 | H17: =+H4*'Resumen operativo'!$D5 | I17: =+I4*'Resumen operativo'!$D5 | J17: =+J4*'Resumen operativo'!$D5 | K17: =+K4*'Resumen operativo'!$D5 | ... O17: =+O4*'Resumen operativo'!$D5 | P17: =SUM(D17:O17) | Q17: =+Q4*'Resumen operativo'!$D5 | R17: =+R4*'Resumen operativo'!$D5 | S17: =+S4*'Resumen operativo'!$D5 | T17: =+T4*'Resumen operativo'!$D5 | U17: =+U4*'Resumen operativo'!$D5 | V17: =+V4*'Resumen operativo'!$D5 | W17: =+W4*'Resumen operativo'!$D5 | X17: =+X4*'Resumen operativo'!$D5 | ... AB17: =+AB4*'Resumen operativo'!$D5 | AC17: =SUM(Q17:AB17)
B18: 3 | C18: =+IF(C5<>"",C5,"") | D18: =+D5*'Resumen operativo'!$D6 | E18: =+E5*'Resumen operativo'!$D6 | F18: =+F5*'Resumen operativo'!$D6 | G18: =+G5*'Resumen operativo'!$D6 | H18: =+H5*'Resumen operativo'!$D6 | I18: =+I5*'Resumen operativo'!$D6 | J18: =+J5*'Resumen operativo'!$D6 | K18: =+K5*'Resumen operativo'!$D6 | ... O18: =+O5*'Resumen operativo'!$D6 | P18: =SUM(D18:O18) | Q18: =+Q5*'Resumen operativo'!$D6 | R18: =+R5*'Resumen operativo'!$D6 | S18: =+S5*'Resumen operativo'!$D6 | T18: =+T5*'Resumen operativo'!$D6 | U18: =+U5*'Resumen operativo'!$D6 | V18: =+V5*'Resumen operativo'!$D6 | W18: =+W5*'Resumen operativo'!$D6 | X18: =+X5*'Resumen operativo'!$D6 | ... AB18: =+AB5*'Resumen operativo'!$D6 | AC18: =SUM(Q18:AB18)
B19: 4 | C19: =+IF(C6<>"",C6,"") | D19: =+D6*'Resumen operativo'!$D7 | E19: =+E6*'Resumen operativo'!$D7 | F19: =+F6*'Resumen operativo'!$D7 | G19: =+G6*'Resumen operativo'!$D7 | H19: =+H6*'Resumen operativo'!$D7 | I19: =+I6*'Resumen operativo'!$D7 | J19: =+J6*'Resumen operativo'!$D7 | K19: =+K6*'Resumen operativo'!$D7 | ... O19: =+O6*'Resumen operativo'!$D7 | P19: =SUM(D19:O19) | Q19: =+Q6*'Resumen operativo'!$D7 | R19: =+R6*'Resumen operativo'!$D7 | S19: =+S6*'Resumen operativo'!$D7 | T19: =+T6*'Resumen operativo'!$D7 | U19: =+U6*'Resumen operativo'!$D7 | V19: =+V6*'Resumen operativo'!$D7 | W19: =+W6*'Resumen operativo'!$D7 | X19: =+X6*'Resumen operativo'!$D7 | ... AB19: =+AB6*'Resumen operativo'!$D7 | AC19: =SUM(Q19:AB19)
B20: 5 | C20: =+IF(C7<>"",C7,"") | D20: =+D7*'Resumen operativo'!$D8 | E20: =+E7*'Resumen operativo'!$D8 | F20: =+F7*'Resumen operativo'!$D8 | G20: =+G7*'Resumen operativo'!$D8 | H20: =+H7*'Resumen operativo'!$D8 | I20: =+I7*'Resumen operativo'!$D8 | J20: =+J7*'Resumen operativo'!$D8 | K20: =+K7*'Resumen operativo'!$D8 | ... O20: =+O7*'Resumen operativo'!$D8 | P20: =SUM(D20:O20) | Q20: =+Q7*'Resumen operativo'!$D8 | R20: =+R7*'Resumen operativo'!$D8 | S20: =+S7*'Resumen operativo'!$D8 | T20: =+T7*'Resumen operativo'!$D8 | U20: =+U7*'Resumen operativo'!$D8 | V20: =+V7*'Resumen operativo'!$D8 | W20: =+W7*'Resumen operativo'!$D8 | X20: =+X7*'Resumen operativo'!$D8 | ... AB20: =+AB7*'Resumen operativo'!$D8 | AC20: =SUM(Q20:AB20)
B21: 6 | C21: =+IF(C8<>"",C8,"") | D21: =+D8*'Resumen operativo'!$D9 | E21: =+E8*'Resumen operativo'!$D9 | F21: =+F8*'Resumen operativo'!$D9 | G21: =+G8*'Resumen operativo'!$D9 | H21: =+H8*'Resumen operativo'!$D9 | I21: =+I8*'Resumen operativo'!$D9 | J21: =+J8*'Resumen operativo'!$D9 | K21: =+K8*'Resumen operativo'!$D9 | ... O21: =+O8*'Resumen operativo'!$D9 | P21: =SUM(D21:O21) | Q21: =+Q8*'Resumen operativo'!$D9 | R21: =+R8*'Resumen operativo'!$D9 | S21: =+S8*'Resumen operativo'!$D9 | T21: =+T8*'Resumen operativo'!$D9 | U21: =+U8*'Resumen operativo'!$D9 | V21: =+V8*'Resumen operativo'!$D9 | W21: =+W8*'Resumen operativo'!$D9 | X21: =+X8*'Resumen operativo'!$D9 | ... AB21: =+AB8*'Resumen operativo'!$D9 | AC21: =SUM(Q21:AB21)
B22: 7 | C22: =+IF(C9<>"",C9,"") | D22: =+D9*'Resumen operativo'!$D10 | E22: =+E9*'Resumen operativo'!$D10 | F22: =+F9*'Resumen operativo'!$D10 | G22: =+G9*'Resumen operativo'!$D10 | H22: =+H9*'Resumen operativo'!$D10 | I22: =+I9*'Resumen operativo'!$D10 | J22: =+J9*'Resumen operativo'!$D10 | K22: =+K9*'Resumen operativo'!$D10 | ... O22: =+O9*'Resumen operativo'!$D10 | P22: =SUM(D22:O22) | Q22: =+Q9*'Resumen operativo'!$D10 | R22: =+R9*'Resumen operativo'!$D10 | S22: =+S9*'Resumen operativo'!$D10 | T22: =+T9*'Resumen operativo'!$D10 | U22: =+U9*'Resumen operativo'!$D10 | V22: =+V9*'Resumen operativo'!$D10 | W22: =+W9*'Resumen operativo'!$D10 | X22: =+X9*'Resumen operativo'!$D10 | ... AB22: =+AB9*'Resumen operativo'!$D10 | AC22: =SUM(Q22:AB22)
B23: 8 | C23: =+IF(C10<>"",C10,"") | D23: =+D10*'Resumen operativo'!$D11 | E23: =+E10*'Resumen operativo'!$D11 | F23: =+F10*'Resumen operativo'!$D11 | G23: =+G10*'Resumen operativo'!$D11 | H23: =+H10*'Resumen operativo'!$D11 | I23: =+I10*'Resumen operativo'!$D11 | J23: =+J10*'Resumen operativo'!$D11 | K23: =+K10*'Resumen operativo'!$D11 | ... O23: =+O10*'Resumen operativo'!$D11 | P23: =SUM(D23:O23) | Q23: =+Q10*'Resumen operativo'!$D11 | R23: =+R10*'Resumen operativo'!$D11 | S23: =+S10*'Resumen operativo'!$D11 | T23: =+T10*'Resumen operativo'!$D11 | U23: =+U10*'Resumen operativo'!$D11 | V23: =+V10*'Resumen operativo'!$D11 | W23: =+W10*'Resumen operativo'!$D11 | X23: =+X10*'Resumen operativo'!$D11 | ... AB23: =+AB10*'Resumen operativo'!$D11 | AC23: =SUM(Q23:AB23)
B24: 9 | C24: =+IF(C11<>"",C11,"") | D24: =+D11*'Resumen operativo'!$D12 | E24: =+E11*'Resumen operativo'!$D12 | F24: =+F11*'Resumen operativo'!$D12 | G24: =+G11*'Resumen operativo'!$D12 | H24: =+H11*'Resumen operativo'!$D12 | I24: =+I11*'Resumen operativo'!$D12 | J24: =+J11*'Resumen operativo'!$D12 | K24: =+K11*'Resumen operativo'!$D12 | ... O24: =+O11*'Resumen operativo'!$D12 | P24: =SUM(D24:O24) | Q24: =+Q11*'Resumen operativo'!$D12 | R24: =+R11*'Resumen operativo'!$D12 | S24: =+S11*'Resumen operativo'!$D12 | T24: =+T11*'Resumen operativo'!$D12 | U24: =+U11*'Resumen operativo'!$D12 | V24: =+V11*'Resumen operativo'!$D12 | W24: =+W11*'Resumen operativo'!$D12 | X24: =+X11*'Resumen operativo'!$D12 | ... AB24: =+AB11*'Resumen operativo'!$D12 | AC24: =SUM(Q24:AB24)
B25: 10 | C25: =+IF(C12<>"",C12,"") | D25: =+D12*'Resumen operativo'!$D13 | E25: =+E12*'Resumen operativo'!$D13 | F25: =+F12*'Resumen operativo'!$D13 | G25: =+G12*'Resumen operativo'!$D13 | H25: =+H12*'Resumen operativo'!$D13 | I25: =+I12*'Resumen operativo'!$D13 | J25: =+J12*'Resumen operativo'!$D13 | K25: =+K12*'Resumen operativo'!$D13 | ... O25: =+O12*'Resumen operativo'!$D13 | P25: =SUM(D25:O25) | Q25: =+Q12*'Resumen operativo'!$D13 | R25: =+R12*'Resumen operativo'!$D13 | S25: =+S12*'Resumen operativo'!$D13 | T25: =+T12*'Resumen operativo'!$D13 | U25: =+U12*'Resumen operativo'!$D13 | V25: =+V12*'Resumen operativo'!$D13 | W25: =+W12*'Resumen operativo'!$D13 | X25: =+X12*'Resumen operativo'!$D13 | ... AB25: =+AB12*'Resumen operativo'!$D13 | AC25: =SUM(Q25:AB25)
C26: Total Ventas en Pesos | D26: =SUM(D16:D25) | E26: =SUM(E16:E25) | F26: =SUM(F16:F25) | G26: =SUM(G16:G25) | H26: =SUM(H16:H25) | I26: =SUM(I16:I25) | J26: =SUM(J16:J25) | K26: =SUM(K16:K25) | ... AC26: =SUM(AC16:AC25)
B28: # | C28: Producción en $ | D28: 1 | E28: 2 | F28: 3 | G28: 4 | H28: 5 | I28: 6 | J28: 7 | K28: 8 | L28: 9 | M28: 10 | N28: 11 | O28: 12 | P28: Total | Q28: 1 | R28: 2 | S28: 3 | T28: 4 | U28: 5 | V28: 6 | W28: 7 | X28: 8 | Y28: 9 | Z28: 10 | AA28: 11 | AB28: 12 | AC28: Total
B29: 1 | C29: =+C16 | D29: =+D3*'Resumen operativo'!$E4 | E29: =+E3*'Resumen operativo'!$E4 | F29: =+F3*'Resumen operativo'!$E4 | G29: =+G3*'Resumen operativo'!$E4 | H29: =+H3*'Resumen operativo'!$E4 | I29: =+I3*'Resumen operativo'!$E4 | J29: =+J3*'Resumen operativo'!$E4 | K29: =+K3*'Resumen operativo'!$E4 | ... O29: =+O3*'Resumen operativo'!$E4 | P29: =SUM(D29:O29) | Q29: =+Q3*'Resumen operativo'!$E4 | R29: =+R3*'Resumen operativo'!$E4 | S29: =+S3*'Resumen operativo'!$E4 | T29: =+T3*'Resumen operativo'!$E4 | U29: =+U3*'Resumen operativo'!$E4 | V29: =+V3*'Resumen operativo'!$E4 | W29: =+W3*'Resumen operativo'!$E4 | X29: =+X3*'Resumen operativo'!$E4 | ... AB29: =+AB3*'Resumen operativo'!$E4 | AC29: =SUM(Q29:AB29)
B30: 2 | C30: =+C17 | D30: =+D4*'Resumen operativo'!$E5 | E30: =+E4*'Resumen operativo'!$E5 | F30: =+F4*'Resumen operativo'!$E5 | G30: =+G4*'Resumen operativo'!$E5 | H30: =+H4*'Resumen operativo'!$E5 | I30: =+I4*'Resumen operativo'!$E5 | J30: =+J4*'Resumen operativo'!$E5 | K30: =+K4*'Resumen operativo'!$E5 | ... O30: =+O4*'Resumen operativo'!$E5 | P30: =SUM(D30:O30) | Q30: =+Q4*'Resumen operativo'!$E5 | R30: =+R4*'Resumen operativo'!$E5 | S30: =+S4*'Resumen operativo'!$E5 | T30: =+T4*'Resumen operativo'!$E5 | U30: =+U4*'Resumen operativo'!$E5 | V30: =+V4*'Resumen operativo'!$E5 | W30: =+W4*'Resumen operativo'!$E5 | X30: =+X4*'Resumen operativo'!$E5 | ... AB30: =+AB4*'Resumen operativo'!$E5 | AC30: =SUM(Q30:AB30)
B31: 3 | C31: =+C18 | D31: =+D5*'Resumen operativo'!$E6 | E31: =+E5*'Resumen operativo'!$E6 | F31: =+F5*'Resumen operativo'!$E6 | G31: =+G5*'Resumen operativo'!$E6 | H31: =+H5*'Resumen operativo'!$E6 | I31: =+I5*'Resumen operativo'!$E6 | J31: =+J5*'Resumen operativo'!$E6 | K31: =+K5*'Resumen operativo'!$E6 | ... O31: =+O5*'Resumen operativo'!$E6 | P31: =SUM(D31:O31) | Q31: =+Q5*'Resumen operativo'!$E6 | R31: =+R5*'Resumen operativo'!$E6 | S31: =+S5*'Resumen operativo'!$E6 | T31: =+T5*'Resumen operativo'!$E6 | U31: =+U5*'Resumen operativo'!$E6 | V31: =+V5*'Resumen operativo'!$E6 | W31: =+W5*'Resumen operativo'!$E6 | X31: =+X5*'Resumen operativo'!$E6 | ... AB31: =+AB5*'Resumen operativo'!$E6 | AC31: =SUM(Q31:AB31)
B32: 4 | C32: =+C19 | D32: =+D6*'Resumen operativo'!$E7 | E32: =+E6*'Resumen operativo'!$E7 | F32: =+F6*'Resumen operativo'!$E7 | G32: =+G6*'Resumen operativo'!$E7 | H32: =+H6*'Resumen operativo'!$E7 | I32: =+I6*'Resumen operativo'!$E7 | J32: =+J6*'Resumen operativo'!$E7 | K32: =+K6*'Resumen operativo'!$E7 | ... O32: =+O6*'Resumen operativo'!$E7 | P32: =SUM(D32:O32) | Q32: =+Q6*'Resumen operativo'!$E7 | R32: =+R6*'Resumen operativo'!$E7 | S32: =+S6*'Resumen operativo'!$E7 | T32: =+T6*'Resumen operativo'!$E7 | U32: =+U6*'Resumen operativo'!$E7 | V32: =+V6*'Resumen operativo'!$E7 | W32: =+W6*'Resumen operativo'!$E7 | X32: =+X6*'Resumen operativo'!$E7 | ... AB32: =+AB6*'Resumen operativo'!$E7 | AC32: =SUM(Q32:AB32)
B33: 5 | C33: =+C20 | D33: =+D7*'Resumen operativo'!$E8 | E33: =+E7*'Resumen operativo'!$E8 | F33: =+F7*'Resumen operativo'!$E8 | G33: =+G7*'Resumen operativo'!$E8 | H33: =+H7*'Resumen operativo'!$E8 | I33: =+I7*'Resumen operativo'!$E8 | J33: =+J7*'Resumen operativo'!$E8 | K33: =+K7*'Resumen operativo'!$E8 | ... O33: =+O7*'Resumen operativo'!$E8 | P33: =SUM(D33:O33) | Q33: =+Q7*'Resumen operativo'!$E8 | R33: =+R7*'Resumen operativo'!$E8 | S33: =+S7*'Resumen operativo'!$E8 | T33: =+T7*'Resumen operativo'!$E8 | U33: =+U7*'Resumen operativo'!$E8 | V33: =+V7*'Resumen operativo'!$E8 | W33: =+W7*'Resumen operativo'!$E8 | X33: =+X7*'Resumen operativo'!$E8 | ... AB33: =+AB7*'Resumen operativo'!$E8 | AC33: =SUM(Q33:AB33)
B34: 6 | C34: =+C21 | D34: =+D8*'Resumen operativo'!$E9 | E34: =+E8*'Resumen operativo'!$E9 | F34: =+F8*'Resumen operativo'!$E9 | G34: =+G8*'Resumen operativo'!$E9 | H34: =+H8*'Resumen operativo'!$E9 | I34: =+I8*'Resumen operativo'!$E9 | J34: =+J8*'Resumen operativo'!$E9 | K34: =+K8*'Resumen operativo'!$E9 | ... O34: =+O8*'Resumen operativo'!$E9 | P34: =SUM(D34:O34) | Q34: =+Q8*'Resumen operativo'!$E9 | R34: =+R8*'Resumen operativo'!$E9 | S34: =+S8*'Resumen operativo'!$E9 | T34: =+T8*'Resumen operativo'!$E9 | U34: =+U8*'Resumen operativo'!$E9 | V34: =+V8*'Resumen operativo'!$E9 | W34: =+W8*'Resumen operativo'!$E9 | X34: =+X8*'Resumen operativo'!$E9 | ... AB34: =+AB8*'Resumen operativo'!$E9 | AC34: =SUM(Q34:AB34)
B35: 7 | C35: =+C22 | D35: =+D9*'Resumen operativo'!$E10 | E35: =+E9*'Resumen operativo'!$E10 | F35: =+F9*'Resumen operativo'!$E10 | G35: =+G9*'Resumen operativo'!$E10 | H35: =+H9*'Resumen operativo'!$E10 | I35: =+I9*'Resumen operativo'!$E10 | J35: =+J9*'Resumen operativo'!$E10 | K35: =+K9*'Resumen operativo'!$E10 | ... O35: =+O9*'Resumen operativo'!$E10 | P35: =SUM(D35:O35) | Q35: =+Q9*'Resumen operativo'!$E10 | R35: =+R9*'Resumen operativo'!$E10 | S35: =+S9*'Resumen operativo'!$E10 | T35: =+T9*'Resumen operativo'!$E10 | U35: =+U9*'Resumen operativo'!$E10 | V35: =+V9*'Resumen operativo'!$E10 | W35: =+W9*'Resumen operativo'!$E10 | X35: =+X9*'Resumen operativo'!$E10 | ... AB35: =+AB9*'Resumen operativo'!$E10 | AC35: =SUM(Q35:AB35)
B36: 8 | C36: =+C23 | D36: =+D10*'Resumen operativo'!$E11 | E36: =+E10*'Resumen operativo'!$E11 | F36: =+F10*'Resumen operativo'!$E11 | G36: =+G10*'Resumen operativo'!$E11 | H36: =+H10*'Resumen operativo'!$E11 | I36: =+I10*'Resumen operativo'!$E11 | J36: =+J10*'Resumen operativo'!$E11 | K36: =+K10*'Resumen operativo'!$E11 | ... O36: =+O10*'Resumen operativo'!$E11 | P36: =SUM(D36:O36) | Q36: =+Q10*'Resumen operativo'!$E11 | R36: =+R10*'Resumen operativo'!$E11 | S36: =+S10*'Resumen operativo'!$E11 | T36: =+T10*'Resumen operativo'!$E11 | U36: =+U10*'Resumen operativo'!$E11 | V36: =+V10*'Resumen operativo'!$E11 | W36: =+W10*'Resumen operativo'!$E11 | X36: =+X10*'Resumen operativo'!$E11 | ... AB36: =+AB10*'Resumen operativo'!$E11 | AC36: =SUM(Q36:AB36)
B37: 9 | C37: =+C24 | D37: =+D11*'Resumen operativo'!$E12 | E37: =+E11*'Resumen operativo'!$E12 | F37: =+F11*'Resumen operativo'!$E12 | G37: =+G11*'Resumen operativo'!$E12 | H37: =+H11*'Resumen operativo'!$E12 | I37: =+I11*'Resumen operativo'!$E12 | J37: =+J11*'Resumen operativo'!$E12 | K37: =+K11*'Resumen operativo'!$E12 | ... O37: =+O11*'Resumen operativo'!$E12 | P37: =SUM(D37:O37) | Q37: =+Q11*'Resumen operativo'!$E12 | R37: =+R11*'Resumen operativo'!$E12 | S37: =+S11*'Resumen operativo'!$E12 | T37: =+T11*'Resumen operativo'!$E12 | U37: =+U11*'Resumen operativo'!$E12 | V37: =+V11*'Resumen operativo'!$E12 | W37: =+W11*'Resumen operativo'!$E12 | X37: =+X11*'Resumen operativo'!$E12 | ... AB37: =+AB11*'Resumen operativo'!$E12 | AC37: =SUM(Q37:AB37)
B38: 10 | C38: =+C25 | D38: =+D12*'Resumen operativo'!$E13 | E38: =+E12*'Resumen operativo'!$E13 | F38: =+F12*'Resumen operativo'!$E13 | G38: =+G12*'Resumen operativo'!$E13 | H38: =+H12*'Resumen operativo'!$E13 | I38: =+I12*'Resumen operativo'!$E13 | J38: =+J12*'Resumen operativo'!$E13 | K38: =+K12*'Resumen operativo'!$E13 | ... O38: =+O12*'Resumen operativo'!$E13 | P38: =SUM(D38:O38) | Q38: =+Q12*'Resumen operativo'!$E13 | R38: =+R12*'Resumen operativo'!$E13 | S38: =+S12*'Resumen operativo'!$E13 | T38: =+T12*'Resumen operativo'!$E13 | U38: =+U12*'Resumen operativo'!$E13 | V38: =+V12*'Resumen operativo'!$E13 | W38: =+W12*'Resumen operativo'!$E13 | X38: =+X12*'Resumen operativo'!$E13 | ... AB38: =+AB12*'Resumen operativo'!$E13 | AC38: =SUM(Q38:AB38)
C39: Total de costos de M.P. | D39: =SUM(D29:D38) | E39: =SUM(E29:E38) | F39: =SUM(F29:F38) | G39: =SUM(G29:G38) | H39: =SUM(H29:H38) | I39: =SUM(I29:I38) | J39: =SUM(J29:J38) | K39: =SUM(K29:K38) | ... AC39: =SUM(AC29:AC38)
B42: # | C42: Clientes nuevos | D42: Mes 1 | E42: Mes 2 | F42: Mes 3 | G42: Mes 4 | H42: Mes 5 | I42: Mes 6 | J42: Mes 7 | K42: Mes 8 | L42: Mes 9 | M42: Mes 10 | N42: Mes 11 | O42: Mes 12 | P42: Total | Q42: Mes 1 | R42: Mes 2 | S42: Mes 3 | T42: Mes 4 | U42: Mes 5 | V42: Mes 6 | W42: Mes 7 | X42: Mes 8 | Y42: Mes 9 | Z42: Mes 10 | AA42: Mes 11 | AB42: Mes 12 | AC42: Total
B43: 1 | C43: =+IF('Resumen operativo'!C4<>"",'Resumen operativo'!C4,"") | P43: =+O43 | AC43: =+AB43
B44: 2 | C44: =+IF('Resumen operativo'!C5<>"",'Resumen operativo'!C5,"") | P44: =+O44 | AC44: =+AB44
B45: 3 | C45: =+IF('Resumen operativo'!C6<>"",'Resumen operativo'!C6,"") | P45: =+O45 | AC45: =+AB45
...

Sheet Proyección financiera
B1: Cifras en pesos mexicanos (MXN)
B2: Tasa de impuestos sobre utilidades del país: | D2: 0.3
B4: Flujo de Fondos | C4: =+'Proyección financiera Insumos'!D2 | D4: =+'Proyección financiera Insumos'!E2 | E4: =+'Proyección financiera Insumos'!F2 | F4: =+'Proyección financiera Insumos'!G2 | G4: =+'Proyección financiera Insumos'!H2 | H4: =+'Proyección financiera Insumos'!I2 | I4: =+'Proyección financiera Insumos'!J2 | J4: =+'Proyección financiera Insumos'!K2 | ... N4: =+'Proyección financiera Insumos'!O2 | O4: Año 1 | P4: =+'Proyección financiera Insumos'!Q2 | Q4: =+'Proyección financiera Insumos'!R2 | R4: =+'Proyección financiera Insumos'!S2 | S4: =+'Proyección financiera Insumos'!T2 | T4: =+'Proyección financiera Insumos'!U2 | U4: =+'Proyección financiera Insumos'!V2 | V4: =+'Proyección financiera Insumos'!W2 | W4: =+'Proyección financiera Insumos'!X2 | ... AA4: =+'Proyección financiera Insumos'!AB2 | AB4: Año 2
B5: Ingresos por Ventas | C5: =+'Proyección financiera Insumos'!D26 | D5: =+'Proyección financiera Insumos'!E26 | E5: =+'Proyección financiera Insumos'!F26 | F5: =+'Proyección financiera Insumos'!G26 | G5: =+'Proyección financiera Insumos'!H26 | H5: =+'Proyección financiera Insumos'!I26 | I5: =+'Proyección financiera Insumos'!J26 | J5: =+'Proyección financiera Insumos'!K26 | ... N5: =+'Proyección financiera Insumos'!O26 | O5: =SUM(C5:N5) | P5: =+'Proyección financiera Insumos'!Q26 | Q5: =+'Proyección financiera Insumos'!R26 | R5: =+'Proyección financiera Insumos'!S26 | S5: =+'Proyección financiera Insumos'!T26 | T5: =+'Proyección financiera Insumos'!U26 | U5: =+'Proyección financiera Insumos'!V26 | V5: =+'Proyección financiera Insumos'!W26 | W5: =+'Proyección financiera Insumos'!X26 | ... AA5: =+'Proyección financiera Insumos'!AB26 | AB5: =SUM(P5:AA5)
B7: Costo de M.P. | C7: =+'Proyección financiera Insumos'!D39 | D7: =+'Proyección financiera Insumos'!E39 | E7: =+'Proyección financiera Insumos'!F39 | F7: =+'Proyección financiera Insumos'!G39 | G7: =+'Proyección financiera Insumos'!H39 | H7: =+'Proyección financiera Insumos'!I39 | I7: =+'Proyección financiera Insumos'!J39 | J7: =+'Proyección financiera Insumos'!K39 | ... N7: =+'Proyección financiera Insumos'!O39 | O7: =SUM(C7:N7) | P7: =+'Proyección financiera Insumos'!Q39 | Q7: =+'Proyección financiera Insumos'!R39 | R7: =+'Proyección financiera Insumos'!S39 | S7: =+'Proyección financiera Insumos'!T39 | T7: =+'Proyección financiera Insumos'!U39 | U7: =+'Proyección financiera Insumos'!V39 | V7: =+'Proyección financiera Insumos'!W39 | W7: =+'Proyección financiera Insumos'!X39 | ... AA7: =+'Proyección financiera Insumos'!AB39 | AB7: =SUM(P7:AA7)
B9: Utilidad Bruta | C9: =+C5-C7 | D9: =+D5-D7 | E9: =+E5-E7 | F9: =+F5-F7 | G9: =+G5-G7 | H9: =+H5-H7 | I9: =+I5-I7 | J9: =+J5-J7 | ... AB9: =+AB5-AB7
B11: Sueldos y Cargas
B12: Sueldos | C12: =+SUM(OPEX!$C$9:$C$22) | D12: =+SUM(OPEX!$C$9:$C$22) | E12: =+SUM(OPEX!$C$9:$C$22) | F12: =+SUM(OPEX!$C$9:$C$22) | G12: =+SUM(OPEX!$C$9:$C$22) | H12: =+SUM(OPEX!$C$9:$C$22) | I12: =+SUM(OPEX!$C$9:$C$22) | J12: =+SUM(OPEX!$C$9:$C$22) | ... N12: =+SUM(OPEX!$C$9:$C$22) | O12: =SUM(C12:N12) | P12: =+SUM(OPEX!$C$9:$C$22) | Q12: =+SUM(OPEX!$C$9:$C$22) | R12: =+SUM(OPEX!$C$9:$C$22) | S12: =+SUM(OPEX!$C$9:$C$22) | T12: =+SUM(OPEX!$C$9:$C$22) | U12: =+SUM(OPEX!$C$9:$C$22) | V12: =+SUM(OPEX!$C$9:$C$22) | W12: =+SUM(OPEX!$C$9:$C$22) | ... AA12: =+SUM(OPEX!$C$9:$C$22) | AB12: =SUM(P12:AA12)
B13: Cargas sociales | C13: =+OPEX!$C$8 | D13: =+OPEX!$C$8 | E13: =+OPEX!$C$8 | F13: =+OPEX!$C$8 | G13: =+OPEX!$C$8 | H13: =+OPEX!$C$8 | I13: =+OPEX!$C$8 | J13: =+OPEX!$C$8 | ... N13: =+OPEX!$C$8 | O13: =SUM(C13:N13) | P13: =+OPEX!$C$8 | Q13: =+OPEX!$C$8 | R13: =+OPEX!$C$8 | S13: =+OPEX!$C$8 | T13: =+OPEX!$C$8 | U13: =+OPEX!$C$8 | V13: =+OPEX!$C$8 | W13: =+OPEX!$C$8 | ... AA13: =+OPEX!$C$8 | AB13: =SUM(P13:AA13)
B14: Subtotal Sueldos y Cargas | C14: =+SUM(C12:C13) | D14: =+SUM(D12:D13) | E14: =+SUM(E12:E13) | F14: =+SUM(F12:F13) | G14: =+SUM(G12:G13) | H14: =+SUM(H12:H13) | I14: =+SUM(I12:I13) | J14: =+SUM(J12:J13) | ... N14: =+SUM(N12:N13) | O14: =SUM(C14:N14) | P14: =+SUM(P12:P13) | Q14: =+SUM(Q12:Q13) | R14: =+SUM(R12:R13) | S14: =+SUM(S12:S13) | T14: =+SUM(T12:T13) | U14: =+SUM(U12:U13) | V14: =+SUM(V12:V13) | W14: =+SUM(W12:W13) | ... AA14: =+SUM(AA12:AA13) | AB14: =SUM(P14:AA14)
B16: Costos indirectos de fábrica | C16: =+OPEX!$E$7-OPEX!$E$8 | D16: =+OPEX!$E$7-OPEX!$E$8 | E16: =+OPEX!$E$7-OPEX!$E$8 | F16: =+OPEX!$E$7-OPEX!$E$8 | G16: =+OPEX!$E$7-OPEX!$E$8 | H16: =+OPEX!$E$7-OPEX!$E$8 | I16: =+OPEX!$E$7-OPEX!$E$8 | J16: =+OPEX!$E$7-OPEX!$E$8 | ... N16: =+OPEX!$E$7-OPEX!$E$8 | O16: =SUM(C16:N16) | P16: =+OPEX!$E$7-OPEX!$E$8 | Q16: =+OPEX!$E$7-OPEX!$E$8 | R16: =+OPEX!$E$7-OPEX!$E$8 | S16: =+OPEX!$E$7-OPEX!$E$8 | T16: =+OPEX!$E$7-OPEX!$E$8 | U16: =+OPEX!$E$7-OPEX!$E$8 | V16: =+OPEX!$E$7-OPEX!$E$8 | W16: =+OPEX!$E$7-OPEX!$E$8 | ... AA16: =+OPEX!$E$7-OPEX!$E$8 | AB16: =SUM(P16:AA16)
B17: Esfuerzo de venta | C17: =+'Proyección financiera Insumos'!D67 | D17: =+'Proyección financiera Insumos'!E67 | E17: =+'Proyección financiera Insumos'!F67 | F17: =+'Proyección financiera Insumos'!G67 | G17: =+'Proyección financiera Insumos'!H67 | H17: =+'Proyección financiera Insumos'!I67 | I17: =+'Proyección financiera Insumos'!J67 | J17: =+'Proyección financiera Insumos'!K67 | ... AB17: =+'Proyección financiera Insumos'!AC67
B19: Total Egresos Operativos | C19: =+C17+C16+C14+C7 | D19: =+D17+D16+D14+D7 | E19: =+E17+E16+E14+E7 | F19: =+F17+F16+F14+F7 | G19: =+G17+G16+G14+G7 | H19: =+H17+H16+H14+H7 | I19: =+I17+I16+I14+I7 | J19: =+J17+J16+J14+J7 | ... N19: =+N17+N16+N14+N7 | O19: =SUM(C19:N19) | P19: =+P17+P16+P14+P7 | Q19: =+Q17+Q16+Q14+Q7 | R19: =+R17+R16+R14+R7 | S19: =+S17+S16+S14+S7 | T19: =+T17+T16+T14+T7 | U19: =+U17+U16+U14+U7 | V19: =+V17+V16+V14+V7 | W19: =+W17+W16+W14+W7 | ... AA19: =+AA17+AA16+AA14+AA7 | AB19: =SUM(P19:AA19)
B21: EBITDA | C21: =+C5-C19 | D21: =+D5-D19 | E21: =+E5-E19 | F21: =+F5-F19 | G21: =+G5-G19 | H21: =+H5-H19 | I21: =+I5-I19 | J21: =+J5-J19 | ... N21: =+N5-N19 | O21: =SUM(C21:N21) | P21: =+P5-P19 | Q21: =+Q5-Q19 | R21: =+R5-R19 | S21: =+S5-S19 | T21: =+T5-T19 | U21: =+U5-U19 | V21: =+V5-V19 | W21: =+W5-W19 | ... AA21: =+AA5-AA19 | AB21: =SUM(P21:AA21)
B23: Depreciación y amortización | C23: =+OPEX!$E$8 | D23: =+OPEX!$E$8 | E23: =+OPEX!$E$8 | F23: =+OPEX!$E$8 | G23: =+OPEX!$E$8 | H23: =+OPEX!$E$8 | I23: =+OPEX!$E$8 | J23: =+OPEX!$E$8 | ... N23: =+OPEX!$E$8 | O23: =+SUM(C23:N23) | P23: =+OPEX!$E$8 | Q23: =+OPEX!$E$8 | R23: =+OPEX!$E$8 | S23: =+OPEX!$E$8 | T23: =+OPEX!$E$8 | U23: =+OPEX!$E$8 | V23: =+OPEX!$E$8 | W23: =+OPEX!$E$8 | ... AA23: =+OPEX!$E$8 | AB23: =+SUM(P23:AA23)
B24: Base gravable | C24: =+C21-C23 | D24: =+D21-D23 | E24: =+E21-E23 | F24: =+F21-F23 | G24: =+G21-G23 | H24: =+H21-H23 | I24: =+I21-I23 | J24: =+J21-J23 | ... AB24: =+AB21-AB23
B25: Impuestos | C25: =+IF(C24>0,C24*$D$2,0) | D25: =+IF(D24>0,D24*$D$2,0) | E25: =+IF(E24>0,E24*$D$2,0) | F25: =+IF(F24>0,F24*$D$2,0) | G25: =+IF(G24>0,G24*$D$2,0) | H25: =+IF(H24>0,H24*$D$2,0) | I25: =+IF(I24>0,I24*$D$2,0) | J25: =+IF(J24>0,J24*$D$2,0) | ... N25: =+IF(N24>0,N24*$D$2,0) | O25: =+SUM(C25:N25) | P25: =+IF(P24>0,P24*$D$2,0) | Q25: =+IF(Q24>0,Q24*$D$2,0) | R25: =+IF(R24>0,R24*$D$2,0) | S25: =+IF(S24>0,S24*$D$2,0) | T25: =+IF(T24>0,T24*$D$2,0) | U25: =+IF(U24>0,U24*$D$2,0) | V25: =+IF(V24>0,V24*$D$2,0) | W25: =+IF(W24>0,W24*$D$2,0) | ... AA25: =+IF(AA24>0,AA24*$D$2,0) | AB25: =+SUM(P25:AA25)
B26: Resultado neto | C26: =+C21-C25 | D26: =+D21-D25 | E26: =+E21-E25 | F26: =+F21-F25 | G26: =+G21-G25 | H26: =+H21-H25 | I26: =+I21-I25 | J26: =+J21-J25 | ... AB26: =+AB21-AB25
B29: Flujo De caja
B30: Necesidad de capital de trabajo | C30: -1400000
B31: Resultado de flujo | C31: =+C26+C23 | D31: =+D26+D23 | E31: =+E26+E23 | F31: =+F26+F23 | G31: =+G26+G23 | H31: =+H26+H23 | I31: =+I26+I23 | J31: =+J26+J23 | ... N31: =+N26+N23 | O31: =+N31 | P31: =+P26+P23 | Q31: =+Q26+Q23 | R31: =+R26+R23 | S31: =+S26+S23 | T31: =+T26+T23 | U31: =+U26+U23 | V31: =+V26+V23 | W31: =+W26+W23 | ... AA31: =+AA26+AA23 | AB31: =+AA31
B32: Balance | C32: =+C31+C30 | D32: =+C32+D31 | E32: =+D32+E31 | F32: =+E32+F31 | G32: =+F32+G31 | H32: =+G32+H31 | I32: =+H32+I31 | J32: =+I32+J31 | K32: =+J32+K31 | ... N32: =+M32+N31 | O32: =+N32 | P32: =+N32+P31 | Q32: =+P32+Q31 | R32: =+Q32+R31 | S32: =+R32+S31 | T32: =+S32+T31 | U32: =+T32+U31 | V32: =+U32+V31 | W32: =+V32+W31 | X32: =+W32+X31 | ... AA32: =+Z32+AA31 | AB32: =+AA32

Sheet Valuación de la empresa
B2: Cifras en pesos mexicanos (MXN)
B4: Necesidad de inversión | C4: =+C5+C6
B5: CAPEX | C5: =+CAPEX!C5
B6: Capital de Trabajo | C6: =+'Proyección financiera'!C30
B7: Costo de capital | C7: 0.22
B9: Porcentage estimado de crecimiento | F9: 0.6 | G9: 0.4 | H9: 0.3
B10: Año | C10: 0 | D10: 1 | E10: 2 | F10: 3 | G10: 4 | H10: 5
B11: Resultado | C11: =-C4 | D11: =+'Proyección financiera'!O26 | E11: =+'Proyección financiera'!AB26 | F11: =+E11*(1+F9) | G11: =+F11*(1+G9) | H11: =+G11*(1+H9)
B12: Valor presente | D12: =D11/(1+$C$7)^D10 | E12: =E11/(1+$C$7)^E10 | F12: =F11/(1+$C$7)^F10 | G12: =G11/(1+$C$7)^G10 | H12: =H11/(1+$C$7)^H10
B13: Valor presente neto | H13: =+SUM(C12:H12)
B14: TIR | H14: =+IF(C11<>0,IRR(C11:H11,),"")
B15: Índice de rentabilidad | H15: =IF(C4<>0,1+H13/C4,"")
B16: % equivalente a la inversión | H16: =IF(H13>0,C4/H13,0)
